<?xml version="1.0" ?>
<robot name="block5">

    <!-- Link1 -->
    <link name="link1">
        <collision>
            <origin rpy="0 0 0" xyz="0 0 0"/>
            <geometry>
                <box size="0.1 0.05 0.05"/>
            </geometry>
        </collision>
        <visual>
        <origin rpy="0 0 0" xyz="0 0 0"/>
            <geometry>
                <box size="0.1 0.05 0.05"/>
            </geometry>
        </visual>
        <inertial>
            <origin rpy="0 0 0" xyz="0.05 0 0"/>
            <mass value="0.05"/>
            <inertia ixx="1e-4" ixy="1e-7" ixz="1e-7" iyy="1e-4" iyz="1e-7" izz="1e-4"/>
        </inertial>
    </link>

    <joint name="Joint1" type="revolute">
        <parent link="link1"/>
        <child link="link2"/>
        <origin rpy="0 0 0" xyz="0.05 0 0"/>
        <axis xyz="0 1 0"/>
        <limit effort="30" lower="-1.57" upper="1.57" velocity="1.571"/>
    </joint>

    <link name="link2">
        <collision>
            <origin rpy="0 0 0" xyz="0.05 0 0"/>
            <geometry>
                <box size="0.1 0.05 0.05"/>
            </geometry>
        </collision>
        <visual>
            <origin rpy="0 0 0" xyz="0.05 0 0"/>
            <geometry>
                <box size="0.1 0.05 0.05"/>
            </geometry>
        </visual>
        <inertial>
            <origin rpy="0 0 0" xyz="0.25 0 0"/>
            <mass value="0.05"/>
            <inertia ixx="1e-4" ixy="1e-7" ixz="1e-7" iyy="1e-4" iyz="1e-7" izz="1e-4"/>
        </inertial>
    </link>

    <joint name="Joint2" type="revolute">
        <parent link="link2"/>
        <child link="link3"/>
        <origin rpy="0 0 0" xyz="0.1 0 0"/>
        <axis xyz="0 1 0"/>
        <limit effort="30" lower="-1.57" upper="1.57" velocity="1.571"/>
    </joint>

    <link name="link3">
        <collision>
            <origin rpy="0 0 0" xyz="0.05 0 0"/>
            <geometry>
                <box size="0.1 0.05 0.05"/>
            </geometry>
        </collision>
        <visual>
            <origin rpy="0 0 0" xyz="0.05 0 0"/>
            <geometry>
                <box size="0.1 0.05 0.05"/>
            </geometry>
        </visual>
        <inertial>
            <origin rpy="0 0 0" xyz="0.05 0 0"/>
            <mass value="0.05"/>
            <inertia ixx="1e-4" ixy="1e-7" ixz="1e-7" iyy="1e-4" iyz="1e-7" izz="1e-4"/>
        </inertial>
    </link>

    <joint name="Joint3" type="revolute">
        <parent link="link3"/>
        <child link="link4"/>
        <origin rpy="0 0 0" xyz="0.1 0 0"/>
        <axis xyz="0 1 0"/>
        <limit effort="30" lower="-1.57" upper="1.57" velocity="1.571"/>
    </joint>

    <link name="link4">
        <collision>
            <origin rpy="0 0 0" xyz="0.05 0 0"/>
            <geometry>
                <box size="0.1 0.05 0.05"/>
            </geometry>
        </collision>
        <visual>
            <origin rpy="0 0 0" xyz="0.05 0 0"/>
            <geometry>
                <box size="0.1 0.05 0.05"/>
            </geometry>
        </visual>
        <inertial>
            <origin rpy="0 0 0" xyz="0.25 0 0"/>
            <mass value="0.05"/>
            <inertia ixx="1e-4" ixy="1e-7" ixz="1e-7" iyy="1e-4" iyz="1e-7" izz="1e-4"/>
        </inertial>
    </link>

    <joint name="Joint4" type="revolute">
        <parent link="link4"/>
        <child link="link5"/>
        <origin rpy="0 0 0" xyz="0.1 0 0"/>
        <axis xyz="0 1 0"/>
        <limit effort="30" lower="-1.57" upper="1.57" velocity="1.571"/>
    </joint>

    <link name="link5">
        <collision>
            <origin rpy="0 0 0" xyz="0.05 0 0"/>
            <geometry>
                <box size="0.1 0.05 0.05"/>
            </geometry>
        </collision>
        <visual>
            <origin rpy="0 0 0" xyz="0.05 0 0"/>
            <geometry>
                <box size="0.1 0.05 0.05"/>
            </geometry>
        </visual>
        <inertial>
            <origin rpy="0 0 0" xyz="0.25 0 0"/>
            <mass value="0.05"/>
            <inertia ixx="1e-4" ixy="1e-7" ixz="1e-7" iyy="1e-4" iyz="1e-7" izz="1e-4"/>
        </inertial>
    </link>


    <transmission name="trans1">
        <type>transmission_interface/SimpleTransmission</type>
        <joint name="Joint1">
            <hardwareInterface>hardware_interface/VelocityJointInterface</hardwareInterface>
        </joint>
        <actuator name="moter1">
            <hardwareInterface>VelocityJointInterface</hardwareInterface>
        </actuator>
    </transmission>

    <transmission name="trans2">
        <type>transmission_interface/SimpleTransmission</type>
        <joint name="Joint2">
            <hardwareInterface>hardware_interface/VelocityJointInterface</hardwareInterface>
        </joint>
        <actuator name="moter2">
            <hardwareInterface>VelocityJointInterface</hardwareInterface>
        </actuator>
    </transmission>

    <transmission name="trans3">
        <type>transmission_interface/SimpleTransmission</type>
        <joint name="Joint3">
            <hardwareInterface>hardware_interface/VelocityJointInterface</hardwareInterface>
        </joint>
        <actuator name="moter3">
            <hardwareInterface>VelocityJointInterface</hardwareInterface>
        </actuator>
    </transmission>

    <transmission name="trans4">
        <type>transmission_interface/SimpleTransmission</type>
        <joint name="Joint4">
            <hardwareInterface>hardware_interface/VelocityJointInterface</hardwareInterface>
        </joint>
        <actuator name="moter4">
            <hardwareInterface>VelocityJointInterface</hardwareInterface>
        </actuator>
    </transmission>


    <gazebo>
        <plugin name="gazebo_ros_control" filename="libgazebo_ros_control.so">
            <robotNamespace>block5</robotNamespace>
            <robotSimType>gazebo_ros_control/DefaultRobotHWSim</robotSimType>
            <legacyModeNS>true</legacyModeNS> 
        </plugin>
    </gazebo>

    <gazebo reference="link1">
      <selfCollide>true</selfCollide>
      <gravity>1</gravity>
      <mu1>10.0</mu1>
      <mu2>10.0</mu2>
      <minDepth>0.002</minDepth>
    </gazebo>

    <gazebo reference="link2">
      <selfCollide>true</selfCollide>
      <gravity>1</gravity>
      <mu1>10.0</mu1>
      <mu2>10.0</mu2>
      <minDepth>0.002</minDepth>
    </gazebo>

    <gazebo reference="link3">
      <selfCollide>true</selfCollide>
      <gravity>1</gravity>
      <mu1>10.0</mu1>
      <mu2>10.0</mu2>
      <minDepth>0.002</minDepth>
    </gazebo>

    <gazebo reference="link4">
      <selfCollide>true</selfCollide>
      <gravity>1</gravity>
      <mu1>10.0</mu1>
      <mu2>10.0</mu2>
      <minDepth>0.002</minDepth>
    </gazebo>

    <gazebo reference="link5">
      <selfCollide>true</selfCollide>
      <gravity>1</gravity>
      <mu1>10.0</mu1>
      <mu2>10.0</mu2>
      <minDepth>0.002</minDepth>
    </gazebo>

</robot>
